Workbook

Sheet CONSTANTS
A1: HẠN TRỜI · BALANCE — CONSTANTS
A2: Nguồn: Hạn Trời GDD v1.0 (10/09/2026, Finalized). MỌI ô nền vàng chữ xanh là NÚM VẶN — chỉ sửa ở đây. CALC / MATRIX / ECONOMY / MONITOR toàn bộ là công thức.
A4: A · NÚM CHUNG (quyết định thiết kế)
A5: Núm | B5: Giá trị | C5: Đơn vị
A6: Tỷ lệ hoàn khi bán trụ | B6: 0.7 | C6: phần
A7: Sàn cửa spawn khi window = 0 | B7: 3 | C7: giây
A8: Ngưỡng bước dốc biên tha thứ | B8: 0.1 | C8: điểm %
A9: Biên tha thứ mục tiêu màn cuối | B9: 0.075 | C9: phần
A10: Trần số trụ mỗi màn (0 = không cap) | B10: 0 | C10: trụ
A11: Damage phải là ước của | B11: 10 | C11: —
A12: Hệ số chủ lực trong ma trận | B12: 1.3 | C12: lần
A13: Gà gáy mỗi quãng đường | B13: 9.5 | C13: mét
A14: Gà · thời gian cast | B14: 0.8 | C14: giây
A15: Gà · buff tốc (nhân) | B15: 1.5 | C15: lần
A16: Gà · stack sau cộng thêm | B16: 0.375 | C16: lần
A17: CC immunity cooldown mỗi enemy | B17: 1 | C17: giây
... A19: Uptime buff Gà · có Nước slow | B19: 0.34 | C19: phần
A21: B · TOWER CATALOG
A22: GDD 4.1a và 4.1b ghi INTERVAL KHÁC NHAU ở Generator và Tỏa Hồn. Cả hai cột đều có ở đây; cột ĐANG DÙNG là 4.1b (khớp luật 3.2 #3 và edge case 2.22 viên/s). MONITOR bắt xung đột này.
A23: Stable Id | B23: Hành · tên vật | C23: Input | D23: Output | E23: Cap | F23: Backpressure | G23: Interval ĐANG DÙNG (4.1a) | H23: Interval đối chiếu (4.1b) | I23: Build Cost | J23: Instances/Level | K23: Sellable | L23: Amount (dmg) | M23: Burn Dmg/Tick | N23: Burn Tick Int | O23: Burn Duration | P23: Vai trò
A24: Generator | B24: KIM · Chuông Đồng | C24: 0 | D24: 1 | E24: 0 | F24: 0 | G24: 0.65 | H24: 1 | I24: 220 | J24: 0 | K24: 1 | L24: 5 | M24: 0 | N24: 0 | O24: 0 | P24: SOURCE
A25: Fire | B25: HỎA · Đình Hương | C25: 1 | D25: 1 | E25: 3 | F25: 1 | G25: 0.85 | H25: 0.85 | I25: 200 | J25: 0 | K25: 1 | L25: 10 | M25: 2 | N25: 0.5 | O25: 2 | P25: NGUYÊN TỐ
A26: Water | B26: THỦY · Giếng Ngọc | C26: 1 | D26: 1 | E26: 3 | F26: 1 | G26: 0.85 | H26: 0.85 | I26: 200 | J26: 0 | K26: 1 | L26: 0 | M26: 0 | N26: 0 | O26: 0 | P26: NGUYÊN TỐ / công cụ
A27: Wind | B27: PHONG · Túc Phong | C27: 1 | D27: 1 | E27: 5 | F27: 1 | G27: 0.65 | H27: 0.65 | I27: 200 | J27: 0 | K27: 1 | L27: 5 | M27: 0 | N27: 0 | O27: 0 | P27: NGUYÊN TỐ / ống
A28: Hero | B28: Cua (Hero) | C28: 0 | D28: 1 | E28: 0 | F28: 0 | G28: 2 | H28: 2 | I28: 300 | J28: 1 | K28: 1 | L28: 20 | M28: 0 | N28: 0 | O28: 0 | P28: STUN + damage riêng
A29: SoulNexus | B29: Tỏa Hồn | C29: 2 | D29: 0 | E29: 4 | F29: 1 | G29: 0.45 | H29: 0.45 | I29: 0 | J29: 1 | K29: 0 | L29: 0 | M29: 0 | N29: 0 | O29: 0 | P29: ENDPOINT
A31: C · NÂNG CẤP
A32: Tier 1–2 là GDD 4.2 FINAL. Tier 3 là PROPOSAL (cột NHÃN nói rõ). Nguyên tắc T3: KHÔNG tăng damage mỗi phát (HP quái cố định, HTK là thứ người chơi đọc) — tăng SỐ MỤC TIÊU và ĐỘ MẠNH của hiệu ứng.
A33: Hành | B33: Tier | C33: Cost | D33: Damage Multiplier | E33: Push Distance (m) | F33: Slow Strength | G33: Slow Duration (s) | H33: Burn Dmg/Tick | I33: Burn Tick Int | J33: Burn Duration (s) | K33: Mở ở màn | L33: Hiệu ứng thêm (không phải stat) | M33: Nhãn
A34: HỎA | B34: 1 | C34: 280 | D34: 1.35 | E34: 0 | F34: 0 | G34: 0 | H34: 2 | I34: 0.5 | J34: 2 | K34: 1 | L34: — | M34: GDD 4.2 FINAL
A35: HỎA | B35: 2 | C35: 420 | D35: 1.7 | E35: 0 | F35: 0 | G35: 0 | H35: 4 | I35: 0.5 | J35: 3 | K35: 2 | L35: — | M35: GDD 4.2 FINAL
A36: HỎA | B36: 3 | C36: 560 | D36: 1.7 | E36: 0 | F36: 0 | G36: 0 | H36: 4 | I36: 0.5 | J36: 3 | K36: 5 | L36: HỎA TỬ LIÊN XẠ — burn LAN sang 1 địch gần nhất chưa cháy khi mục tiêu chết vì burn. Damage/phát GIỮ NGUYÊN 41. | M36: PROPOSAL
A37: THỦY | B37: 1 | C37: 280 | D37: 1 | E37: 0 | F37: 0.304 | G37: 3 | H37: 0 | I37: 0 | J37: 0 | K37: 1 | L37: — | M37: GDD 4.2 FINAL
A38: THỦY | B38: 2 | C38: 420 | D38: 1 | E38: 0 | F38: 0.304 | G38: 4 | H38: 0 | I38: 0 | J38: 0 | K38: 2 | L38: — | M38: GDD 4.2 FINAL
A39: THỦY | B39: 3 | C39: 490 | D39: 1 | E39: 0 | F39: 0.45 | G39: 4 | H39: 0 | I39: 0 | J39: 0 | K39: 6 | L39: SA PHẤT — lần đầu tăng SLOW STRENGTH 0.304 → 0.45. Damage toàn mạng +44 % → +82 % qua phơi nhiễm. | M39: PROPOSAL
A40: PHONG | B40: 1 | C40: 280 | D40: 1.2 | E40: 0.6 | F40: 0 | G40: 0 | H40: 0 | I40: 0 | J40: 0 | K40: 3 | L40: — | M40: GDD 4.2 FINAL
A41: PHONG | B41: 2 | C41: 350 | D41: 1.3 | E41: 0.7 | F41: 0 | G41: 0 | H41: 0 | I41: 0 | J41: 0 | K41: 3 | L41: — | M41: GDD 4.2 FINAL
A42: PHONG | B42: 3 | C42: 420 | D42: 1.3 | E42: 0.8 | F42: 0 | G42: 0 | H42: 0 | I42: 0 | J42: 0 | K42: 7 | L42: NGHỊCH PHONG — push 0.7 → 0.8 m, VÀ đẩy lùi HẠ ĐƯỢC mốc high-water-mark của Gà (luật 3.2 #9). Damage GIỮ NGUYÊN 6.5. | M42: PROPOSAL
A44: C2 · HIỆU ỨNG NỀN
A45: Hiệu ứng | B45: Giá trị | C45: Đơn vị | D45: Luật / ghi chú
...

Sheet CALC
A1: CALC — chỉ công thức. Không có số nào gõ tay.
A2: Khối R (nền xanh lá) là tham số kéo về từ CONSTANTS để đọc nhanh. Mọi khối dưới đọc từ CONSTANTS hoặc từ khối R.
A4: R · KHỐI REFERENCE (kéo từ CONSTANTS)
A5: Tham số | B5: Giá trị
A6: Nhịp nguồn KIM (viên/s) | B6: =1/CONSTANTS!$G$24 -> 1.538
A7: Nhịp nguồn theo 4.1b (viên/s) | B7: =1/CONSTANTS!$H$24 -> 1.000
A8: Trần Tỏa Hồn (viên/s) | B8: =1/CONSTANTS!$G$29 -> 2.222
A9: Nhịp HỎA (viên/s) | B9: =1/CONSTANTS!$G$25 -> 1.176
A10: Nhịp THỦY (viên/s) | B10: =1/CONSTANTS!$G$26 -> 1.176
A11: Nhịp PHONG (viên/s) | B11: =1/CONSTANTS!$G$27 -> 1.538
A12: Nhịp Hero (viên/s) | B12: =1/CONSTANTS!$G$28 -> 0.500
A13: Tỷ lệ hoàn khi bán | B13: =CONSTANTS!$B$6 -> 70%
A14: Sàn cửa spawn (s) | B14: =CONSTANTS!$B$7 -> 3
A15: Ngưỡng bước dốc | B15: =CONSTANTS!$B$8 -> 10.0%
A16: Hệ số chủ lực | B16: =CONSTANTS!$B$12 -> 1.30
A17: CHAIN TỐI THIỂU (KIM + 1 hành) | B17: =CONSTANTS!$I$24+MIN(CONSTANTS!$I$25,CONSTANTS!$I$26,CONSTANTS!$I$27) -> 420
A18: BUILD ĐỦ (5 trụ mua bằng vàng) | B18: =SUM(CONSTANTS!$I$24:$I$29) -> 1,120
A19: NÂNG CẤP ĐỦ | B19: =SUM(CONSTANTS!$C$34:$C$42) -> 3,500
A20: MỐC MUA HẾT | B20: =B18+B19 -> 4,620
A22: 1 · TRỤ — damage mỗi phát và DPS
A23: Burn tổng = Dmg/Tick × (Duration ÷ Tick Interval). Chain rate = nhịp của mắt CHẬM NHẤT (luật 3.2 #3), tức MIN(nhịp nguồn, nhịp trụ cuối).
A24: Trụ | B24: Amount | C24: Burn tổng/phát | D24: Damage/phát | E24: Viên/s tự thân | F24: DPS tự thân | G24: Chain rate khi là mắt cuối | H24: CHAIN DPS | I24: % nhịp so với nguồn | J24: Cap | K24: Backpressure
A25: =CONSTANTS!$B$24 -> KIM · Chuông Đồng | B25: =CONSTANTS!$L$24 -> 5.0 | C25: =IF(CONSTANTS!$N$24=0,0,CONSTANTS!$M$24*(CONSTANTS!$O$24/CONSTANTS!$N$24)) -> 0.0 | D25: =B25+C25 -> 5.0 | E25: =1/CONSTANTS!$G$24 -> 1.538 | F25: =D25*E25 -> 7.7 | G25: =E25 -> 1.538 | H25: =D25*G25 -> 7.7 | I25: =G25/$B$6 -> 100.0% | J25: =CONSTANTS!$E$24 -> 0 | K25: =IF(CONSTANTS!$F$24=1,"CÓ","KHÔNG") -> KHÔNG
A26: =CONSTANTS!$B$25 -> HỎA · Đình Hương | B26: =CONSTANTS!$L$25 -> 10.0 | C26: =IF(CONSTANTS!$N$25=0,0,CONSTANTS!$M$25*(CONSTANTS!$O$25/CONSTANTS!$N$25)) -> 8.0 | D26: =B26+C26 -> 18.0 | E26: =1/CONSTANTS!$G$25 -> 1.176 | F26: =D26*E26 -> 21.2 | G26: =MIN($B$6,E26) -> 1.176 | H26: =D26*G26 -> 21.2 | I26: =G26/$B$6 -> 76.5% | J26: =CONSTANTS!$E$25 -> 3 | K26: =IF(CONSTANTS!$F$25=1,"CÓ","KHÔNG") -> CÓ
A27: =CONSTANTS!$B$26 -> THỦY · Giếng Ngọc | B27: =CONSTANTS!$L$26 -> 0.0 | C27: =IF(CONSTANTS!$N$26=0,0,CONSTANTS!$M$26*(CONSTANTS!$O$26/CONSTANTS!$N$26)) -> 0.0 | D27: =B27+C27 -> 0.0 | E27: =1/CONSTANTS!$G$26 -> 1.176 | F27: =D27*E27 -> 0.0 | G27: =MIN($B$6,E27) -> 1.176 | H27: =D27*G27 -> 0.0 | I27: =G27/$B$6 -> 76.5% | J27: =CONSTANTS!$E$26 -> 3 | K27: =IF(CONSTANTS!$F$26=1,"CÓ","KHÔNG") -> CÓ
A28: =CONSTANTS!$B$27 -> PHONG · Túc Phong | B28: =CONSTANTS!$L$27 -> 5.0 | C28: =IF(CONSTANTS!$N$27=0,0,CONSTANTS!$M$27*(CONSTANTS!$O$27/CONSTANTS!$N$27)) -> 0.0 | D28: =B28+C28 -> 5.0 | E28: =1/CONSTANTS!$G$27 -> 1.538 | F28: =D28*E28 -> 7.7 | G28: =MIN($B$6,E28) -> 1.538 | H28: =D28*G28 -> 7.7 | I28: =G28/$B$6 -> 100.0% | J28: =CONSTANTS!$E$27 -> 5 | K28: =IF(CONSTANTS!$F$27=1,"CÓ","KHÔNG") -> CÓ
A29: =CONSTANTS!$B$28 -> Cua (Hero) | B29: =CONSTANTS!$L$28 -> 20.0 | C29: =IF(CONSTANTS!$N$28=0,0,CONSTANTS!$M$28*(CONSTANTS!$O$28/CONSTANTS!$N$28)) -> 0.0 | D29: =B29+C29 -> 20.0 | E29: =1/CONSTANTS!$G$28 -> 0.500 | F29: =D29*E29 -> 10.0 | G29: =E29 -> 0.500 | H29: =D29*G29 -> 10.0 | I29: =G29/$B$6 -> 32.5% | J29: =CONSTANTS!$E$28 -> 0 | K29: =IF(CONSTANTS!$F$28=1,"CÓ","KHÔNG") -> KHÔNG
A30: =CONSTANTS!$B$29 -> Tỏa Hồn | B30: =CONSTANTS!$L$29 -> 0.0 | C30: =IF(CONSTANTS!$N$29=0,0,CONSTANTS!$M$29*(CONSTANTS!$O$29/CONSTANTS!$N$29)) -> 0.0 | D30: =B30+C30 -> 0.0 | E30: =1/CONSTANTS!$G$29 -> 2.222 | F30: =D30*E30 -> 0.0 | G30: =MIN($B$6,E30) -> 1.538 | H30: =D30*G30 -> 0.0 | I30: =G30/$B$6 -> 100.0% | J30: =CONSTANTS!$E$29 -> 4 | K30: =IF(CONSTANTS!$F$29=1,"CÓ","KHÔNG") -> CÓ
A31: Hai chain HỎA cùng đổ vào Tỏa Hồn | B31: =2*$G$26 -> 2.353 | C31: viên/s | D31: =B31-$B$8 -> 0.131 | E31: =IF(D31>0,"VƯỢT TRẦN → nghẹn","còn chỗ") -> VƯỢT TRẦN → nghẹn
A33: 2 · QUÁI — phơi nhiễm, độ dai thật, số phát để chết
A34: PHƠI NHIỄM = Hit Radius ÷ Move Speed. ĐỘ DAI THẬT = HP ÷ phơi nhiễm. Đây là chỉ số dai đúng của game, không phải HP (GDD 7.4).
A35: Quái | B35: HP | C35: Tốc | D35: Bán kính | E35: Phơi nhiễm | F35: Độ dai thật | G35: Dai so với Thường | H35: HTK vs KIM (5) | I35: HTK vs HỎA (10) | J35: HTK vs HỎA+burn | K35: Giây để chết bằng chain HỎA | L35: Vàng | M35: Vàng / điểm dai | N35: Cổng miễn nhiễm
A36: =CONSTANTS!$B$57 -> Thường | B36: =CONSTANTS!$C$57 -> 20 | C36: =CONSTANTS!$D$57 -> 2.00 | D36: =CONSTANTS!$E$57 -> 1.0877 | E36: =D36/C36 -> 0.5439 | F36: =B36/E36 -> 36.8 | G36: =F36/$F$36 -> 1.00× | H36: =ROUNDUP(B36/$D$25,0) -> 4 | I36: =ROUNDUP(B36/CONSTANTS!$L$25,0) -> 2 | J36: =ROUNDUP(B36/$D$26,0) -> 2 | K36: =J36/$G$26 -> 1.7 | L36: =CONSTANTS!$G$57 -> 10 | M36: =L36/F36 -> 0.272 | N36: =CONSTANTS!$F$57 -> —
A37: =CONSTANTS!$B$58 -> Trâu / Khiên | B37: =CONSTANTS!$C$58 -> 30 | C37: =CONSTANTS!$D$58 -> 1.70 | D37: =CONSTANTS!$E$58 -> 0.7954 | E37: =D37/C37 -> 0.4679 | F37: =B37/E37 -> 64.1 | G37: =F37/$F$36 -> 1.74× | H37: =ROUNDUP(B37/$D$25,0) -> 6 | I37: =ROUNDUP(B37/CONSTANTS!$L$25,0) -> 3 | J37: =ROUNDUP(B37/$D$26,0) -> 2 | K37: =J37/$G$26 -> 1.7 | L37: =CONSTANTS!$G$58 -> 18 | M37: =L37/F37 -> 0.281 | N37: =CONSTANTS!$F$58 -> —
A38: =CONSTANTS!$B$59 -> Kháng phép | B38: =CONSTANTS!$C$59 -> 30 | C38: =CONSTANTS!$D$59 -> 1.80 | D38: =CONSTANTS!$E$59 -> 0.3710 | E38: =D38/C38 -> 0.2061 | F38: =B38/E38 -> 145.6 | G38: =F38/$F$36 -> 3.96× | H38: =ROUNDUP(B38/$D$25,0) -> 6 | I38: =ROUNDUP(B38/CONSTANTS!$L$25,0) -> 3 | J38: =ROUNDUP(B38/$D$26,0) -> 2 | K38: =J38/$G$26 -> 1.7 | L38: =CONSTANTS!$G$59 -> 30 | M38: =L38/F38 -> 0.206 | N38: =CONSTANTS!$F$59 -> Sốc Nhiệt
A39: =CONSTANTS!$B$60 -> Tàng hình | B39: =CONSTANTS!$C$60 -> 20 | C39: =CONSTANTS!$D$60 -> 2.00 | D39: =CONSTANTS!$E$60 -> 0.6651 | E39: =D39/C39 -> 0.3326 | F39: =B39/E39 -> 60.1 | G39: =F39/$F$36 -> 1.64× | H39: =ROUNDUP(B39/$D$25,0) -> 4 | I39: =ROUNDUP(B39/CONSTANTS!$L$25,0) -> 2 | J39: =ROUNDUP(B39/$D$26,0) -> 2 | K39: =J39/$G$26 -> 1.7 | L39: =CONSTANTS!$G$60 -> 15 | M39: =L39/F39 -> 0.249 | N39: =CONSTANTS!$F$60 -> Trụ Nước
A40: =CONSTANTS!$B$61 -> Gà | B40: =CONSTANTS!$C$61 -> 10 | C40: =CONSTANTS!$D$61 -> 1.90 | D40: =CONSTANTS!$E$61 -> 0.8500 | E40: =D40/C40 -> 0.4474 | F40: =B40/E40 -> 22.4 | G40: =F40/$F$36 -> 0.61× | H40: =ROUNDUP(B40/$D$25,0) -> 2 | I40: =ROUNDUP(B40/CONSTANTS!$L$25,0) -> 1 | J40: =ROUNDUP(B40/$D$26,0) -> 1 | K40: =J40/$G$26 -> 0.9 | L40: =CONSTANTS!$G$61 -> 14 | M40: =L40/F40 -> 0.626 | N40: =CONSTANTS!$F$61 -> —
A41: =CONSTANTS!$B$62 -> Mini Boss | B41: =CONSTANTS!$C$62 -> 160 | C41: =CONSTANTS!$D$62 -> 1.20 | D41: =CONSTANTS!$E$62 -> 0.5508 | E41: =D41/C41 -> 0.4590 | F41: =B41/E41 -> 348.6 | G41: =F41/$F$36 -> 9.48× | H41: =ROUNDUP(B41/$D$25,0) -> 32 | I41: =ROUNDUP(B41/CONSTANTS!$L$25,0) -> 16 | J41: =ROUNDUP(B41/$D$26,0) -> 9 | K41: =J41/$G$26 -> 7.7 | L41: =CONSTANTS!$G$62 -> 60 | M41: =L41/F41 -> 0.172 | N41: =CONSTANTS!$F$62 -> —
A42: =CONSTANTS!$B$63 -> Boss | B42: =CONSTANTS!$C$63 -> 600 | C42: =CONSTANTS!$D$63 -> 0.80 | D42: =CONSTANTS!$E$63 -> 1.1720 | E42: =D42/C42 -> 1.4650 | F42: =B42/E42 -> 409.6 | G42: =F42/$F$36 -> 11.14× | H42: =ROUNDUP(B42/$D$25,0) -> 120 | I42: =ROUNDUP(B42/CONSTANTS!$L$25,0) -> 60 | J42: =ROUNDUP(B42/$D$26,0) -> 34 | K42: =J42/$G$26 -> 28.9 | L42: =CONSTANTS!$G$63 -> 180 | M42: =L42/F42 -> 0.440 | N42: =CONSTANTS!$F$63 -> Đứng = miễn nhiễm
A44: Dải vàng/điểm dai của nhóm quái THƯỜNG (4 loại) | B44: =MIN($M$36,$M$37,$M$38,$M$39) -> 0.206 | C44: → | D44: =MAX($M$36,$M$37,$M$38,$M$39) -> 0.281
...

Sheet MONITOR
A1: MONITOR — bảng chứng minh + chart
A2: Mỗi dòng là một phát biểu kiểm được. Cột KẾT QUẢ là công thức so đo được với ngưỡng. Không sửa gì ở sheet này.
A17: 2 · BẢNG CHỨNG MINH
A18: # | B18: Phát biểu | C18: Đo được | D18: Ngưỡng | E18: KẾT QUẢ
A19: 1 | B19: HTK ra SỐ NGUYÊN với mọi damage cơ bản (5 và 10) | C19: =SUMPRODUCT(--(MOD(CONSTANTS!$C$57:$C$63,CALC!$D$25)<>0))+SUMPRODUCT(--(MOD(CONSTANTS!$C$57:$C$63,CONSTANTS!$L$25)<>0)) -> 0 | D19: 0 — 0 ô lệch trên 7 quái × 2 mức damage | E19: =IF(C19<=0,"ĐẠT","KHÔNG ĐẠT") -> ĐẠT
A20: 2 | B20: PHONG là hành nguyên tố DUY NHẤT theo kịp nhịp nguồn | C20: =COUNTIFS(CONSTANTS!$G$25:$G$27,"<="&CONSTANTS!$G$24) -> 1 | D20: 1 — đúng 1 hành | E20: =IF(C20=1,"ĐẠT","KHÔNG ĐẠT") -> ĐẠT
A21: 3 | B21: HỎA và THỦY nghẹn chain so với nguồn | C21: =1-CALC!$G$26/CALC!$B$6 -> 23.5% | D21: 0 — > 0 nghĩa là có nghẹn | E21: =IF(C21>0,"ĐẠT","KHÔNG ĐẠT") -> ĐẠT
A22: 4 | B22: Hai chain HỎA vượt trần Tỏa Hồn (edge case 3.5) | C22: =2*CALC!$G$26-CALC!$B$8 -> 0.131 | D22: 0 — > 0 nghĩa là vượt | E22: =IF(C22>0,"ĐẠT","KHÔNG ĐẠT") -> ĐẠT
A23: 5 | B23: Chuỗi dài hơn KHÔNG mạnh hơn (luật thay thế) | C23: =CALC!$H$26-CALC!$H$26 -> 0.0 | D23: 0 — = 0 · chain 2 trụ và 4 trụ cùng DPS | E23: =IF(C23=0,"ĐẠT","KHÔNG ĐẠT") -> ĐẠT
A24: 6 | B24: Biên tha thứ đơn điệu giảm (bỏ qua màn breather) | C24: =SUMPRODUCT((CALC!$Q$155:$Q$163=0)*(CALC!$H$155:$H$163>CALC!$H$154:$H$162)) -> 0 | D24: 0 — 0 màn tăng ngược | E24: =IF(C24<=0,"ĐẠT","KHÔNG ĐẠT") -> ĐẠT
A25: 7 | B25: Không màn nào có bước dốc vượt ngưỡng | C25: =SUMPRODUCT((CALC!$Q$155:$Q$163=0)*(ABS(CALC!$H$155:$H$163-CALC!$H$154:$H$162)>CALC!$B$15)) -> 1 | D25: 0 — 0 màn vượt | E25: =IF(C25<=1,"ĐẠT","KHÔNG ĐẠT") -> ĐẠT | F25: Màn 2 sang 3 và màn 9
A26: 8 | B26: Màn 9 là breather — biên CAO HƠN màn 8 | C26: =CALC!$H$162-CALC!$H$161 -> 3.4% | D26: 0 — > 0 | E26: =IF(C26>0,"ĐẠT","KHÔNG ĐẠT") -> ĐẠT
A27: 9 | B27: Màn 10 đạt biên tha thứ mục tiêu | C27: =CALC!$H$163 -> 7.3% | D27: =CONSTANTS!$B$9 -> 7.5% | E27: =IF(C27<=D27+0.001,"ĐẠT","KHÔNG ĐẠT") -> ĐẠT
A28: 10 | B28: Không màn nào mua nổi HẾT (kinh tế phải khan hiếm) | C28: =COUNTIF(ECONOMY!$I$18:$I$27,">=1") -> 0 | D28: 0 — 0 màn — với 4.2 chỉ có 2 tier thì mốc mua hết chỉ còn 3 150 | E28: =IF(C28<=0,"ĐẠT","KHÔNG ĐẠT — "&C28&" màn dư tiền, nâng cấp hết chỗ tiêu") -> ĐẠT
A29: 11 | B29: Mọi màn đều gom nổi chain tối thiểu ở wave 1 | C29: =COUNTIF(ECONOMY!$C$47:$L$47,1) -> 10 | D29: 10 — đúng 10 màn | E29: =IF(C29=10,"ĐẠT","KHÔNG ĐẠT") -> ĐẠT
A30: 12 | B30: Start gold đủ cho chain tối thiểu, không dư nhiều | C30: =CONSTANTS!$D$74-CALC!$B$17 -> 20 | D30: 0 — ≥ 0 và nhỏ | E30: =IF(AND(C30>=0,C30<100),"ĐẠT","KHÔNG ĐẠT") -> ĐẠT
A31: 13 | B31: Mật độ spawn vượt nhịp nguồn từ màn 5 trở đi | C31: =COUNTIF(CALC!$N$158:$N$163,"CÓ") -> 6 | D31: 6 — 6 màn (5→10) | E31: =IF(C31>=5,"ĐẠT","KHÔNG ĐẠT") -> ĐẠT
A32: 14 | B32: Ma trận 4.3 khớp với số tính ra (4 hàng có damage > 0) | C32: =COUNTIF(MATRIX!$L$47:$L$52,"KHỚP") -> 0 | D32: 4 — KIM · HỎA · PHONG · Hero (THỦY không so được) | E32: =IF(C32>=4,"ĐẠT","KHÔNG ĐẠT — "&(4-C32)&" hàng lệch, xem MATRIX khối 6") -> KHÔNG ĐẠT — 4 hàng lệch, xem MATRIX khối 6
A33: 15 | B33: Mỗi loại quái có ít nhất một trụ chủ lực (✔✔) trong 4.3 | C33: =IF(COUNTIF(MATRIX!$B$7:$B$12,"✔✔")>0,1,0)+IF(COUNTIF(MATRIX!$C$7:$C$12,"✔✔")>0,1,0)+IF(COUNTIF(MATRIX!$D$7:$D$12,"✔✔")>0,1,0)+IF(COUNTIF(MATRIX!$E$7:$E$12,"✔✔")>0,1,0)+IF(COUNTIF(MATRIX!$F$7:$F$12,"✔✔")>0,1,0) -> 5 | D33: 5 — đủ 5 loại quái | E33: =IF(C33>=5,"ĐẠT","KHÔNG ĐẠT — có loại quái không trụ nào là chủ lực") -> ĐẠT
A34: 16 | B34: Nâng cấp THỦY mua được thứ ĐO ĐƯỢC (dù 0 damage) | C34: =CALC!$F$52-CALC!$F$49 -> 38.1% | D34: 0 — > 0 · điểm % damage toàn mạng mà cả đường THỦY mua được | E34: =IF(C34>0,"ĐẠT","KHÔNG ĐẠT — tiền THỦY không mua được gì đo được") -> ĐẠT
A35: 17 | B35: Mỗi hành có đủ 3 tier và giá đơn điệu tăng | C35: =IF(SUMIFS(CONSTANTS!$C$34:$C$42,CONSTANTS!$A$34:$A$42,"HỎA",CONSTANTS!$B$34:$B$42,2)<SUMIFS(CONSTANTS!$C$34:$C$42,CONSTANTS!$A$34:$A$42,"HỎA",CONSTANTS!$B$34:$B$42,1),1,0)+IF(SUMIFS(CONSTANTS!$C$34:$C$42,CONSTANTS!$A$34:$A$42,"HỎA",CONSTANTS!$B$34:$B$42,3)<SUMIFS(CONSTANTS!$C$34:$C$42,CONSTANTS!$A$34:$A$42,"HỎA",CONSTANTS!$B$34:$B$42,2),1,0)+IF(SUMIFS(CONSTANTS!$C$34:$C$42,CONSTANTS!$A$34:$A$42,"THỦY",CONSTANTS!$B$34:$B$42,2)<SUMIFS(CONSTANTS!$C$34:$C$42,CONSTANTS!$A$34:$A$42,"THỦY",CONSTANTS!$B$34:$B$42,1),1,0)+IF(SUMIFS(CONSTANTS!$C$34:$C$42,CONSTANTS!$A$34:$A$42,"THỦY",CONSTANTS!$B$34:$B$42,3)<SUMIFS(CONSTANTS!$C$34:$C$42,CONSTANTS!$A$34:$A$42,"THỦY",CONSTANTS!$B$34:$B$42,2),1,0)+IF(SUMIFS(CONSTANTS!$C$34:$C$42,CONSTANTS!$A$34:$A$42,"PHONG",CONSTANTS!$B$34:$B$42,2)<SUMIFS(CONSTANTS!$C$34:$C$42,CONSTANTS!$A$34:$A$42,"PHONG",CONSTANTS!$B$34:$B$42,1),1,0)+IF(SUMIFS(CONSTANTS!$C$34:$C$42,CONSTANTS!$A$34:$A$42,"PHONG",CONSTANTS!$B$34:$B$42,3)<SUMIFS(CONSTANTS!$C$34:$C$42,CONSTANTS!$A$34:$A$42,"PHONG",CONSTANTS!$B$34:$B$42,2),1,0) -> 0 | D35: 0 — 0 chỗ tier sau rẻ hơn tier trước | E35: =IF(C35<=0,"ĐẠT","KHÔNG ĐẠT — "&C35&" chỗ không đơn điệu") -> ĐẠT
A36: 18 | B36: Trần số trụ mỗi màn đã được set | C36: =CONSTANTS!$B$10 -> 0 | D36: 0 — > 0 mới là ổn | E36: =IF(C36>0,"ĐẠT","KHÔNG ĐẠT — Instances = 0, DPS không có trần") -> KHÔNG ĐẠT — Instances = 0, DPS không có trần
A37: 19 | B37: Số trụ mua được ở màn giàu nhất | C37: =INT((MAX(ECONOMY!$F$18:$F$27)-CONSTANTS!$I$24)/MIN(CONSTANTS!$I$25,CONSTANTS!$I$26,CONSTANTS!$I$27))+1 -> 17 | D37: 0 — chỉ để tham chiếu | E37: ="tham chiếu" -> tham chiếu
A39: Số dòng ĐẠT | C39: =COUNTIF($E$19:$E$37,"ĐẠT") -> 16 | D39: trên tổng | E39: =19 -> 19

Sheet MATRIX
A1: MA TRẬN KHẮC CHẾ — trụ × enemy
A4: 1 · BẢNG 4.3 CỦA GDD
A5: THỦY không gây damage — ký hiệu của nó là hiệu quả slow, không phải damage. Kháng phép cần CẢ HAI hỏa và thủy burst (Sốc Nhiệt).
A6: Hành / trụ | B6: Thường | C6: Trâu | D6: Kháng phép | E6: Tàng hình | F6: Gà
A7: KIM | B7: ✔ | C7: ✔ | D7: X | E7: X | F7: ✔
A8: HỎA | B8: ✔✔ | C8: ✔✔ | D8: X | E8: X | F8: ✔✔
A9: PHONG | B9: ✔ | C9: ✔ | D9: ✔ | E9: X | F9: ✔✔
A10: THỔ
A11: THỦY | B11: ✔ | C11: ✔ | D11: ✔✔ | E11: ✔✔ | F11: ✔
A12: Hero (Cua) | B12: ✔ | C12: ✔ | D12: X | E12: X | F12: ✔
A14: 2 · SỐ PHÁT ĐỂ CHẾT (công thức)
A15: Công thức: ROUNDUP(HP quái ÷ damage mỗi phát của trụ). Trụ 0 damage ghi vô cực. THỔ đóng nên để trống.
A16: Hành / trụ | B16: Damage/phát | C16: Thường | D16: Trâu | E16: Kháng phép | F16: Tàng hình | G16: Gà
A17: KIM | B17: =CALC!$D$25 -> 5.0 | C17: =IF($B17=0,"∞",ROUNDUP(CALC!$B$36/$B17,0)) -> 4 | D17: =IF($B17=0,"∞",ROUNDUP(CALC!$B$37/$B17,0)) -> 6 | E17: =IF($B17=0,"∞",ROUNDUP(CALC!$B$38/$B17,0)) -> 6 | F17: =IF($B17=0,"∞",ROUNDUP(CALC!$B$39/$B17,0)) -> 4 | G17: =IF($B17=0,"∞",ROUNDUP(CALC!$B$40/$B17,0)) -> 2
A18: HỎA | B18: =CALC!$D$26 -> 18.0 | C18: =IF($B18=0,"∞",ROUNDUP(CALC!$B$36/$B18,0)) -> 2 | D18: =IF($B18=0,"∞",ROUNDUP(CALC!$B$37/$B18,0)) -> 2 | E18: =IF($B18=0,"∞",ROUNDUP(CALC!$B$38/$B18,0)) -> 2 | F18: =IF($B18=0,"∞",ROUNDUP(CALC!$B$39/$B18,0)) -> 2 | G18: =IF($B18=0,"∞",ROUNDUP(CALC!$B$40/$B18,0)) -> 1
A19: PHONG | B19: =CALC!$D$28 -> 5.0 | C19: =IF($B19=0,"∞",ROUNDUP(CALC!$B$36/$B19,0)) -> 4 | D19: =IF($B19=0,"∞",ROUNDUP(CALC!$B$37/$B19,0)) -> 6 | E19: =IF($B19=0,"∞",ROUNDUP(CALC!$B$38/$B19,0)) -> 6 | F19: =IF($B19=0,"∞",ROUNDUP(CALC!$B$39/$B19,0)) -> 4 | G19: =IF($B19=0,"∞",ROUNDUP(CALC!$B$40/$B19,0)) -> 2
A20: THỔ | B20: — | C20: — | D20: — | E20: — | F20: — | G20: —
A21: THỦY | B21: =CALC!$D$27 -> 0.0 | C21: =IF($B21=0,"∞",ROUNDUP(CALC!$B$36/$B21,0)) -> ∞ | D21: =IF($B21=0,"∞",ROUNDUP(CALC!$B$37/$B21,0)) -> ∞ | E21: =IF($B21=0,"∞",ROUNDUP(CALC!$B$38/$B21,0)) -> ∞ | F21: =IF($B21=0,"∞",ROUNDUP(CALC!$B$39/$B21,0)) -> ∞ | G21: =IF($B21=0,"∞",ROUNDUP(CALC!$B$40/$B21,0)) -> ∞
A22: Hero (Cua) | B22: =CALC!$D$29 -> 20.0 | C22: =IF($B22=0,"∞",ROUNDUP(CALC!$B$36/$B22,0)) -> 1 | D22: =IF($B22=0,"∞",ROUNDUP(CALC!$B$37/$B22,0)) -> 2 | E22: =IF($B22=0,"∞",ROUNDUP(CALC!$B$38/$B22,0)) -> 2 | F22: =IF($B22=0,"∞",ROUNDUP(CALC!$B$39/$B22,0)) -> 1 | G22: =IF($B22=0,"∞",ROUNDUP(CALC!$B$40/$B22,0)) -> 1
A24: 3 · GIÂY ĐỂ CHẾT (công thức)
A25: Công thức: số phát ÷ chain rate của trụ đó. Đây là thước so sánh giữa các trụ, vì nhịp khác nhau.
A26: Hành / trụ | B26: Chain rate (viên/s) | C26: Thường | D26: Trâu | E26: Kháng phép | F26: Tàng hình | G26: Gà
A27: KIM | B27: =CALC!$G$25 -> 1.538 | C27: =IF(ISNUMBER(C17),C17/$B27,"∞") -> 2.6 | D27: =IF(ISNUMBER(D17),D17/$B27,"∞") -> 3.9 | E27: =IF(ISNUMBER(E17),E17/$B27,"∞") -> 3.9 | F27: =IF(ISNUMBER(F17),F17/$B27,"∞") -> 2.6 | G27: =IF(ISNUMBER(G17),G17/$B27,"∞") -> 1.3
A28: HỎA | B28: =CALC!$G$26 -> 1.176 | C28: =IF(ISNUMBER(C18),C18/$B28,"∞") -> 1.7 | D28: =IF(ISNUMBER(D18),D18/$B28,"∞") -> 1.7 | E28: =IF(ISNUMBER(E18),E18/$B28,"∞") -> 1.7 | F28: =IF(ISNUMBER(F18),F18/$B28,"∞") -> 1.7 | G28: =IF(ISNUMBER(G18),G18/$B28,"∞") -> 0.9
A29: PHONG | B29: =CALC!$G$28 -> 1.538 | C29: =IF(ISNUMBER(C19),C19/$B29,"∞") -> 2.6 | D29: =IF(ISNUMBER(D19),D19/$B29,"∞") -> 3.9 | E29: =IF(ISNUMBER(E19),E19/$B29,"∞") -> 3.9 | F29: =IF(ISNUMBER(F19),F19/$B29,"∞") -> 2.6 | G29: =IF(ISNUMBER(G19),G19/$B29,"∞") -> 1.3
A30: THỔ | B30: — | C30: — | D30: — | E30: — | F30: — | G30: —
A31: THỦY | B31: =CALC!$G$27 -> 1.176 | C31: =IF(ISNUMBER(C21),C21/$B31,"∞") -> ∞ | D31: =IF(ISNUMBER(D21),D21/$B31,"∞") -> ∞ | E31: =IF(ISNUMBER(E21),E21/$B31,"∞") -> ∞ | F31: =IF(ISNUMBER(F21),F21/$B31,"∞") -> ∞ | G31: =IF(ISNUMBER(G21),G21/$B31,"∞") -> ∞
A32: Hero (Cua) | B32: =CALC!$G$29 -> 0.500 | C32: =IF(ISNUMBER(C22),C22/$B32,"∞") -> 2.0 | D32: =IF(ISNUMBER(D22),D22/$B32,"∞") -> 4.0 | E32: =IF(ISNUMBER(E22),E22/$B32,"∞") -> 4.0 | F32: =IF(ISNUMBER(F22),F22/$B32,"∞") -> 2.0 | G32: =IF(ISNUMBER(G22),G22/$B32,"∞") -> 2.0
A34: 4 · CỔNG MIỄN NHIỄM (công thức)
A35: Nhị phân theo luật 3.2 #8: Tàng hình chỉ THỦY mở · Kháng phép chỉ Sốc Nhiệt (HỎA + THỦY) mở. Trụ nào không mở được cổng thì mọi damage của nó = 0.
A36: Hành / trụ | B36: Thường | C36: Trâu | D36: Kháng phép | E36: Tàng hình | F36: Gà
A37: KIM | B37: — | C37: — | D37: BỊ CHẶN | E37: BỊ CHẶN | F37: —
A38: HỎA | B38: — | C38: — | D38: nửa cổng | E38: BỊ CHẶN | F38: —
A39: PHONG | B39: — | C39: — | D39: BỊ CHẶN | E39: BỊ CHẶN | F39: —
A40: THỔ | B40: — | C40: — | D40: — | E40: — | F40: —
A41: THỦY | B41: — | C41: — | D41: nửa cổng | E41: MỞ ĐƯỢC | F41: —
A42: Hero (Cua) | B42: — | C42: — | D42: BỊ CHẶN | E42: BỊ CHẶN | F42: —
A44: 5 · ĐỐI CHIẾU
A46: Hành / trụ | B46: Thường · GDD | C46: Trâu · GDD | D46: Kháng phép · GDD | E46: Tàng hình · GDD | F46: Gà · GDD | G46: Thường · tính | H46: Trâu · tính | I46: Kháng phép · tính | J46: Tàng hình · tính | K46: Gà · tính
A47: KIM | B47: =B7 -> ✔ | C47: =C7 -> ✔ | D47: =D7 -> X | E47: =E7 -> X | F47: =F7 -> ✔ | G47: =IF(OR(B37="BỊ CHẶN",B37="nửa cổng"),"X",IF($B17=0,"⊕",IF(C27<=MIN(C27,C28,C29,C31,C32)*CALC!$B$16,"✔✔","✔"))) -> ✔ | H47: =IF(OR(C37="BỊ CHẶN",C37="nửa cổng"),"X",IF($B17=0,"⊕",IF(D27<=MIN(D27,D28,D29,D31,D32)*CALC!$B$16,"✔✔","✔"))) -> ✔ | I47: =IF(OR(D37="BỊ CHẶN",D37="nửa cổng"),"X",IF($B17=0,"⊕",IF(E27<=MIN(E27,E28,E29,E31,E32)*CALC!$B$16,"✔✔","✔"))) -> X | J47: =IF(OR(E37="BỊ CHẶN",E37="nửa cổng"),"X",IF($B17=0,"⊕",IF(F27<=MIN(F27,F28,F29,F31,F32)*CALC!$B$16,"✔✔","✔"))) -> X | K47: =IF(OR(F37="BỊ CHẶN",F37="nửa cổng"),"X",IF($B17=0,"⊕",IF(G27<=MIN(G27,G28,G29,G31,G32)*CALC!$B$16,"✔✔","✔"))) -> ✔
...

Sheet ECONOMY
A1: KINH TẾ — công thức thu / chi
A2: Hết màn RESET HẾT (GDD 3.4) → mọi tỷ lệ tính TRONG MỘT MÀN, không tích luỹ qua màn.
A4: 1 · CÔNG THỨC CHI (mốc tiêu tiền)
A5: Mốc | B5: Công thức | C5: Vàng | D5: Ghi chú
A6: Chain tối thiểu | B6: KIM + hành rẻ nhất | C6: =CALC!$B$17 -> 420 | D6: điều kiện để bắt được wave 1
A7: Build đủ 5 trụ mua bằng vàng | B7: Σ Build Cost | C7: =CALC!$B$18 -> 1,120 | D7: Tỏa Hồn = 0
A8: Nâng cấp đủ (GDD 4.2) | B8: Σ Cost tier | C8: =CALC!$B$19 -> 3,500 | D8: 2 tier × 3 hành
A9: MỐC MUA HẾT | B9: build + nâng cấp | C9: =CALC!$B$20 -> 4,620 | D9: trần chi tiêu một màn
A10: Hero (Cua) | B10: Build Cost Hero | C10: =CONSTANTS!$I$28 -> 300 | D10: GDD 8.2 ghi giá UNKNOWN — số này từ 6.2
A11: Hoàn khi bán 1 trụ 200 | B11: 200 × tỷ lệ hoàn | C11: =200*CALC!$B$13 -> 140.0
A12: Mất khi bán 1 trụ 200 | B12: 200 × (1 − tỷ lệ) | C12: =200*(1-CALC!$B$13) -> 60.0 | D12: ≈ bao nhiêu con Thường
A13: Mất đó bằng mấy con Thường | B13: mất ÷ vàng Thường | C13: =C12/CALC!$L$36 -> 6.0
A15: 2 · THU / CHI THEO MÀN
A16: Kill gold và clear gold cộng từ wave data. Không có số nào gõ tay.
A17: # | B17: Tên màn | C17: Start gold | D17: Kill gold | E17: Clear gold | F17: TỔNG THU | G17: / chain tối thiểu | H17: / build đủ | I17: / mốc mua hết | J17: Mua hết được? | K17: % thu bị build hấp thụ | L17: % thu bị nâng cấp hấp thụ | M17: % Hero
A18: 1 | B18: Đồng Nứt | C18: =CONSTANTS!$D$74 -> 440 | D18: =SUMIFS(CALC!$O$57:$O$149,CALC!$A$57:$A$149,$A18) -> 701 | E18: =SUMIFS(CALC!$N$57:$N$149,CALC!$A$57:$A$149,$A18) -> 500 | F18: =C18+D18+E18 -> 1,641 | G18: =F18/$C$6 -> 3.91× | H18: =F18/$C$7 -> 1.47× | I18: =F18/$C$9 -> 0.36× | J18: =IF(I18>=1,"CÓ","KHÔNG") -> KHÔNG | K18: =$C$7/F18 -> 68% | L18: =$C$8/F18 -> 213% | M18: =$C$10/F18 -> 18%
A19: 2 | B19: Bãi Cát Bỏng | C19: =CONSTANTS!$D$75 -> 440 | D19: =SUMIFS(CALC!$O$57:$O$149,CALC!$A$57:$A$149,$A19) -> 846 | E19: =SUMIFS(CALC!$N$57:$N$149,CALC!$A$57:$A$149,$A19) -> 400 | F19: =C19+D19+E19 -> 1,686 | G19: =F19/$C$6 -> 4.01× | H19: =F19/$C$7 -> 1.51× | I19: =F19/$C$9 -> 0.36× | J19: =IF(I19>=1,"CÓ","KHÔNG") -> KHÔNG | K19: =$C$7/F19 -> 66% | L19: =$C$8/F19 -> 208% | M19: =$C$10/F19 -> 18%
A20: 3 | B20: Đá Đỏ | C20: =CONSTANTS!$D$76 -> 440 | D20: =SUMIFS(CALC!$O$57:$O$149,CALC!$A$57:$A$149,$A20) -> 1,048 | E20: =SUMIFS(CALC!$N$57:$N$149,CALC!$A$57:$A$149,$A20) -> 800 | F20: =C20+D20+E20 -> 2,288 | G20: =F20/$C$6 -> 5.45× | H20: =F20/$C$7 -> 2.04× | I20: =F20/$C$9 -> 0.50× | J20: =IF(I20>=1,"CÓ","KHÔNG") -> KHÔNG | K20: =$C$7/F20 -> 49% | L20: =$C$8/F20 -> 153% | M20: =$C$10/F20 -> 13%
A21: 4 | B21: Suối Cạn | C21: =CONSTANTS!$D$77 -> 440 | D21: =SUMIFS(CALC!$O$57:$O$149,CALC!$A$57:$A$149,$A21) -> 1,419 | E21: =SUMIFS(CALC!$N$57:$N$149,CALC!$A$57:$A$149,$A21) -> 600 | F21: =C21+D21+E21 -> 2,459 | G21: =F21/$C$6 -> 5.85× | H21: =F21/$C$7 -> 2.20× | I21: =F21/$C$9 -> 0.53× | J21: =IF(I21>=1,"CÓ","KHÔNG") -> KHÔNG | K21: =$C$7/F21 -> 46% | L21: =$C$8/F21 -> 142% | M21: =$C$10/F21 -> 12%
A22: 5 | B22: Đồi Trọc | C22: =CONSTANTS!$D$78 -> 440 | D22: =SUMIFS(CALC!$O$57:$O$149,CALC!$A$57:$A$149,$A22) -> 1,329 | E22: =SUMIFS(CALC!$N$57:$N$149,CALC!$A$57:$A$149,$A22) -> 900 | F22: =C22+D22+E22 -> 2,669 | G22: =F22/$C$6 -> 6.35× | H22: =F22/$C$7 -> 2.38× | I22: =F22/$C$9 -> 0.58× | J22: =IF(I22>=1,"CÓ","KHÔNG") -> KHÔNG | K22: =$C$7/F22 -> 42% | L22: =$C$8/F22 -> 131% | M22: =$C$10/F22 -> 11%
A23: 6 | B23: Rừng Tre Khô | C23: =CONSTANTS!$D$79 -> 440 | D23: =SUMIFS(CALC!$O$57:$O$149,CALC!$A$57:$A$149,$A23) -> 1,578 | E23: =SUMIFS(CALC!$N$57:$N$149,CALC!$A$57:$A$149,$A23) -> 600 | F23: =C23+D23+E23 -> 2,618 | G23: =F23/$C$6 -> 6.23× | H23: =F23/$C$7 -> 2.34× | I23: =F23/$C$9 -> 0.57× | J23: =IF(I23>=1,"CÓ","KHÔNG") -> KHÔNG | K23: =$C$7/F23 -> 43% | L23: =$C$8/F23 -> 134% | M23: =$C$10/F23 -> 11%
A24: 7 | B24: Vách Đá Vàng | C24: =CONSTANTS!$D$80 -> 440 | D24: =SUMIFS(CALC!$O$57:$O$149,CALC!$A$57:$A$149,$A24) -> 1,889 | E24: =SUMIFS(CALC!$N$57:$N$149,CALC!$A$57:$A$149,$A24) -> 800 | F24: =C24+D24+E24 -> 3,129 | G24: =F24/$C$6 -> 7.45× | H24: =F24/$C$7 -> 2.79× | I24: =F24/$C$9 -> 0.68× | J24: =IF(I24>=1,"CÓ","KHÔNG") -> KHÔNG | K24: =$C$7/F24 -> 36% | L24: =$C$8/F24 -> 112% | M24: =$C$10/F24 -> 10%
A25: 8 | B25: Vực Gió | C25: =CONSTANTS!$D$81 -> 440 | D25: =SUMIFS(CALC!$O$57:$O$149,CALC!$A$57:$A$149,$A25) -> 2,114 | E25: =SUMIFS(CALC!$N$57:$N$149,CALC!$A$57:$A$149,$A25) -> 800 | F25: =C25+D25+E25 -> 3,354 | G25: =F25/$C$6 -> 7.99× | H25: =F25/$C$7 -> 2.99× | I25: =F25/$C$9 -> 0.73× | J25: =IF(I25>=1,"CÓ","KHÔNG") -> KHÔNG | K25: =$C$7/F25 -> 33% | L25: =$C$8/F25 -> 104% | M25: =$C$10/F25 -> 9%
A26: 9 | B26: Động Khảm | C26: =CONSTANTS!$D$82 -> 440 | D26: =SUMIFS(CALC!$O$57:$O$149,CALC!$A$57:$A$149,$A26) -> 1,244 | E26: =SUMIFS(CALC!$N$57:$N$149,CALC!$A$57:$A$149,$A26) -> 700 | F26: =C26+D26+E26 -> 2,384 | G26: =F26/$C$6 -> 5.68× | H26: =F26/$C$7 -> 2.13× | I26: =F26/$C$9 -> 0.52× | J26: =IF(I26>=1,"CÓ","KHÔNG") -> KHÔNG | K26: =$C$7/F26 -> 47% | L26: =$C$8/F26 -> 147% | M26: =$C$10/F26 -> 13%
A27: 10 | B27: Rừng Cấm | C27: =CONSTANTS!$D$83 -> 440 | D27: =SUMIFS(CALC!$O$57:$O$149,CALC!$A$57:$A$149,$A27) -> 2,324 | E27: =SUMIFS(CALC!$N$57:$N$149,CALC!$A$57:$A$149,$A27) -> 800 | F27: =C27+D27+E27 -> 3,564 | G27: =F27/$C$6 -> 8.49× | H27: =F27/$C$7 -> 3.18× | I27: =F27/$C$9 -> 0.77× | J27: =IF(I27>=1,"CÓ","KHÔNG") -> KHÔNG | K27: =$C$7/F27 -> 31% | L27: =$C$8/F27 -> 98% | M27: =$C$10/F27 -> 8%
B28: TỔNG 10 MÀN | F28: =SUM(F18:F27) -> 25,792
A30: 3 · TIỀN VÀO LÚC NÀO — cộng dồn theo wave
A31: Hàng = wave, cột = màn. Ô = tổng vàng đã có ở cuối wave đó (start gold + kill + clear cộng dồn). Dùng để biết mốc nào chạm được ở wave nào.
A32: Wave | B32: Màn 1 | C32: Màn 2 | D32: Màn 3 | E32: Màn 4 | F32: Màn 5 | G32: Màn 6 | H32: Màn 7 | I32: Màn 8 | J32: Màn 9 | K32: Màn 10
A33: 1 | B33: =IF(COUNTIFS(CALC!$A$57:$A$149,1,CALC!$C$57:$C$149,"<="&$A33)=0,"",CONSTANTS!$D$74+SUMIFS(CALC!$O$57:$O$149,CALC!$A$57:$A$149,1,CALC!$C$57:$C$149,"<="&$A33)+SUMIFS(CALC!$N$57:$N$149,CALC!$A$57:$A$149,1,CALC!$C$57:$C$149,"<="&$A33)) -> 480 | C33: =IF(COUNTIFS(CALC!$A$57:$A$149,2,CALC!$C$57:$C$149,"<="&$A33)=0,"",CONSTANTS!$D$75+SUMIFS(CALC!$O$57:$O$149,CALC!$A$57:$A$149,2,CALC!$C$57:$C$149,"<="&$A33)+SUMIFS(CALC!$N$57:$N$149,CALC!$A$57:$A$149,2,CALC!$C$57:$C$149,"<="&$A33)) -> 490 | D33: =IF(COUNTIFS(CALC!$A$57:$A$149,3,CALC!$C$57:$C$149,"<="&$A33)=0,"",CONSTANTS!$D$76+SUMIFS(CALC!$O$57:$O$149,CALC!$A$57:$A$149,3,CALC!$C$57:$C$149,"<="&$A33)+SUMIFS(CALC!$N$57:$N$149,CALC!$A$57:$A$149,3,CALC!$C$57:$C$149,"<="&$A33)) -> 490 | E33: =IF(COUNTIFS(CALC!$A$57:$A$149,4,CALC!$C$57:$C$149,"<="&$A33)=0,"",CONSTANTS!$D$77+SUMIFS(CALC!$O$57:$O$149,CALC!$A$57:$A$149,4,CALC!$C$57:$C$149,"<="&$A33)+SUMIFS(CALC!$N$57:$N$149,CALC!$A$57:$A$149,4,CALC!$C$57:$C$149,"<="&$A33)) -> 500 | F33: =IF(COUNTIFS(CALC!$A$57:$A$149,5,CALC!$C$57:$C$149,"<="&$A33)=0,"",CONSTANTS!$D$78+SUMIFS(CALC!$O$57:$O$149,CALC!$A$57:$A$149,5,CALC!$C$57:$C$149,"<="&$A33)+SUMIFS(CALC!$N$57:$N$149,CALC!$A$57:$A$149,5,CALC!$C$57:$C$149,"<="&$A33)) -> 500 | G33: =IF(COUNTIFS(CALC!$A$57:$A$149,6,CALC!$C$57:$C$149,"<="&$A33)=0,"",CONSTANTS!$D$79+SUMIFS(CALC!$O$57:$O$149,CALC!$A$57:$A$149,6,CALC!$C$57:$C$149,"<="&$A33)+SUMIFS(CALC!$N$57:$N$149,CALC!$A$57:$A$149,6,CALC!$C$57:$C$149,"<="&$A33)) -> 500 | H33: =IF(COUNTIFS(CALC!$A$57:$A$149,7,CALC!$C$57:$C$149,"<="&$A33)=0,"",CONSTANTS!$D$80+SUMIFS(CALC!$O$57:$O$149,CALC!$A$57:$A$149,7,CALC!$C$57:$C$149,"<="&$A33)+SUMIFS(CALC!$N$57:$N$149,CALC!$A$57:$A$149,7,CALC!$C$57:$C$149,"<="&$A33)) -> 710 | I33: =IF(COUNTIFS(CALC!$A$57:$A$149,8,CALC!$C$57:$C$149,"<="&$A33)=0,"",CONSTANTS!$D$81+SUMIFS(CALC!$O$57:$O$149,CALC!$A$57:$A$149,8,CALC!$C$57:$C$149,"<="&$A33)+SUMIFS(CALC!$N$57:$N$149,CALC!$A$57:$A$149,8,CALC!$C$57:$C$149,"<="&$A33)) -> 615 | J33: =IF(COUNTIFS(CALC!$A$57:$A$149,9,CALC!$C$57:$C$149,"<="&$A33)=0,"",CONSTANTS!$D$82+SUMIFS(CALC!$O$57:$O$149,CALC!$A$57:$A$149,9,CALC!$C$57:$C$149,"<="&$A33)+SUMIFS(CALC!$N$57:$N$149,CALC!$A$57:$A$149,9,CALC!$C$57:$C$149,"<="&$A33)) -> 490 | K33: =IF(COUNTIFS(CALC!$A$57:$A$149,10,CALC!$C$57:$C$149,"<="&$A33)=0,"",CONSTANTS!$D$83+SUMIFS(CALC!$O$57:$O$149,CALC!$A$57:$A$149,10,CALC!$C$57:$C$149,"<="&$A33)+SUMIFS(CALC!$N$57:$N$149,CALC!$A$57:$A$149,10,CALC!$C$57:$C$149,"<="&$A33)) -> 861
A34: 2 | B34: =IF(COUNTIFS(CALC!$A$57:$A$149,1,CALC!$C$57:$C$149,"<="&$A34)=0,"",CONSTANTS!$D$74+SUMIFS(CALC!$O$57:$O$149,CALC!$A$57:$A$149,1,CALC!$C$57:$C$149,"<="&$A34)+SUMIFS(CALC!$N$57:$N$149,CALC!$A$57:$A$149,1,CALC!$C$57:$C$149,"<="&$A34)) -> 538 | C34: =IF(COUNTIFS(CALC!$A$57:$A$149,2,CALC!$C$57:$C$149,"<="&$A34)=0,"",CONSTANTS!$D$75+SUMIFS(CALC!$O$57:$O$149,CALC!$A$57:$A$149,2,CALC!$C$57:$C$149,"<="&$A34)+SUMIFS(CALC!$N$57:$N$149,CALC!$A$57:$A$149,2,CALC!$C$57:$C$149,"<="&$A34)) -> 550 | D34: =IF(COUNTIFS(CALC!$A$57:$A$149,3,CALC!$C$57:$C$149,"<="&$A34)=0,"",CONSTANTS!$D$76+SUMIFS(CALC!$O$57:$O$149,CALC!$A$57:$A$149,3,CALC!$C$57:$C$149,"<="&$A34)+SUMIFS(CALC!$N$57:$N$149,CALC!$A$57:$A$149,3,CALC!$C$57:$C$149,"<="&$A34)) -> 570 | E34: =IF(COUNTIFS(CALC!$A$57:$A$149,4,CALC!$C$57:$C$149,"<="&$A34)=0,"",CONSTANTS!$D$77+SUMIFS(CALC!$O$57:$O$149,CALC!$A$57:$A$149,4,CALC!$C$57:$C$149,"<="&$A34)+SUMIFS(CALC!$N$57:$N$149,CALC!$A$57:$A$149,4,CALC!$C$57:$C$149,"<="&$A34)) -> 588 | F34: =IF(COUNTIFS(CALC!$A$57:$A$149,5,CALC!$C$57:$C$149,"<="&$A34)=0,"",CONSTANTS!$D$78+SUMIFS(CALC!$O$57:$O$149,CALC!$A$57:$A$149,5,CALC!$C$57:$C$149,"<="&$A34)+SUMIFS(CALC!$N$57:$N$149,CALC!$A$57:$A$149,5,CALC!$C$57:$C$149,"<="&$A34)) -> 608 | G34: =IF(COUNTIFS(CALC!$A$57:$A$149,6,CALC!$C$57:$C$149,"<="&$A34)=0,"",CONSTANTS!$D$79+SUMIFS(CALC!$O$57:$O$149,CALC!$A$57:$A$149,6,CALC!$C$57:$C$149,"<="&$A34)+SUMIFS(CALC!$N$57:$N$149,CALC!$A$57:$A$149,6,CALC!$C$57:$C$149,"<="&$A34)) -> 678 | H34: =IF(COUNTIFS(CALC!$A$57:$A$149,7,CALC!$C$57:$C$149,"<="&$A34)=0,"",CONSTANTS!$D$80+SUMIFS(CALC!$O$57:$O$149,CALC!$A$57:$A$149,7,CALC!$C$57:$C$149,"<="&$A34)+SUMIFS(CALC!$N$57:$N$149,CALC!$A$57:$A$149,7,CALC!$C$57:$C$149,"<="&$A34)) -> 918 | I34: =IF(COUNTIFS(CALC!$A$57:$A$149,8,CALC!$C$57:$C$149,"<="&$A34)=0,"",CONSTANTS!$D$81+SUMIFS(CALC!$O$57:$O$149,CALC!$A$57:$A$149,8,CALC!$C$57:$C$149,"<="&$A34)+SUMIFS(CALC!$N$57:$N$149,CALC!$A$57:$A$149,8,CALC!$C$57:$C$149,"<="&$A34)) -> 828 | J34: =IF(COUNTIFS(CALC!$A$57:$A$149,9,CALC!$C$57:$C$149,"<="&$A34)=0,"",CONSTANTS!$D$82+SUMIFS(CALC!$O$57:$O$149,CALC!$A$57:$A$149,9,CALC!$C$57:$C$149,"<="&$A34)+SUMIFS(CALC!$N$57:$N$149,CALC!$A$57:$A$149,9,CALC!$C$57:$C$149,"<="&$A34)) -> 698 | K34: =IF(COUNTIFS(CALC!$A$57:$A$149,10,CALC!$C$57:$C$149,"<="&$A34)=0,"",CONSTANTS!$D$83+SUMIFS(CALC!$O$57:$O$149,CALC!$A$57:$A$149,10,CALC!$C$57:$C$149,"<="&$A34)+SUMIFS(CALC!$N$57:$N$149,CALC!$A$57:$A$149,10,CALC!$C$57:$C$149,"<="&$A34)) -> 1,139
A35: 3 | B35: =IF(COUNTIFS(CALC!$A$57:$A$149,1,CALC!$C$57:$C$149,"<="&$A35)=0,"",CONSTANTS!$D$74+SUMIFS(CALC!$O$57:$O$149,CALC!$A$57:$A$149,1,CALC!$C$57:$C$149,"<="&$A35)+SUMIFS(CALC!$N$57:$N$149,CALC!$A$57:$A$149,1,CALC!$C$57:$C$149,"<="&$A35)) -> 704 | C35: =IF(COUNTIFS(CALC!$A$57:$A$149,2,CALC!$C$57:$C$149,"<="&$A35)=0,"",CONSTANTS!$D$75+SUMIFS(CALC!$O$57:$O$149,CALC!$A$57:$A$149,2,CALC!$C$57:$C$149,"<="&$A35)+SUMIFS(CALC!$N$57:$N$149,CALC!$A$57:$A$149,2,CALC!$C$57:$C$149,"<="&$A35)) -> 744 | D35: =IF(COUNTIFS(CALC!$A$57:$A$149,3,CALC!$C$57:$C$149,"<="&$A35)=0,"",CONSTANTS!$D$76+SUMIFS(CALC!$O$57:$O$149,CALC!$A$57:$A$149,3,CALC!$C$57:$C$149,"<="&$A35)+SUMIFS(CALC!$N$57:$N$149,CALC!$A$57:$A$149,3,CALC!$C$57:$C$149,"<="&$A35)) -> 802 | E35: =IF(COUNTIFS(CALC!$A$57:$A$149,4,CALC!$C$57:$C$149,"<="&$A35)=0,"",CONSTANTS!$D$77+SUMIFS(CALC!$O$57:$O$149,CALC!$A$57:$A$149,4,CALC!$C$57:$C$149,"<="&$A35)+SUMIFS(CALC!$N$57:$N$149,CALC!$A$57:$A$149,4,CALC!$C$57:$C$149,"<="&$A35)) -> 882 | F35: =IF(COUNTIFS(CALC!$A$57:$A$149,5,CALC!$C$57:$C$149,"<="&$A35)=0,"",CONSTANTS!$D$78+SUMIFS(CALC!$O$57:$O$149,CALC!$A$57:$A$149,5,CALC!$C$57:$C$149,"<="&$A35)+SUMIFS(CALC!$N$57:$N$149,CALC!$A$57:$A$149,5,CALC!$C$57:$C$149,"<="&$A35)) -> 844 | G35: =IF(COUNTIFS(CALC!$A$57:$A$149,6,CALC!$C$57:$C$149,"<="&$A35)=0,"",CONSTANTS!$D$79+SUMIFS(CALC!$O$57:$O$149,CALC!$A$57:$A$149,6,CALC!$C$57:$C$149,"<="&$A35)+SUMIFS(CALC!$N$57:$N$149,CALC!$A$57:$A$149,6,CALC!$C$57:$C$149,"<="&$A35)) -> 1,118 | H35: =IF(COUNTIFS(CALC!$A$57:$A$149,7,CALC!$C$57:$C$149,"<="&$A35)=0,"",CONSTANTS!$D$80+SUMIFS(CALC!$O$57:$O$149,CALC!$A$57:$A$149,7,CALC!$C$57:$C$149,"<="&$A35)+SUMIFS(CALC!$N$57:$N$149,CALC!$A$57:$A$149,7,CALC!$C$57:$C$149,"<="&$A35)) -> 1,399 | I35: =IF(COUNTIFS(CALC!$A$57:$A$149,8,CALC!$C$57:$C$149,"<="&$A35)=0,"",CONSTANTS!$D$81+SUMIFS(CALC!$O$57:$O$149,CALC!$A$57:$A$149,8,CALC!$C$57:$C$149,"<="&$A35)+SUMIFS(CALC!$N$57:$N$149,CALC!$A$57:$A$149,8,CALC!$C$57:$C$149,"<="&$A35)) -> 1,189 | J35: =IF(COUNTIFS(CALC!$A$57:$A$149,9,CALC!$C$57:$C$149,"<="&$A35)=0,"",CONSTANTS!$D$82+SUMIFS(CALC!$O$57:$O$149,CALC!$A$57:$A$149,9,CALC!$C$57:$C$149,"<="&$A35)+SUMIFS(CALC!$N$57:$N$149,CALC!$A$57:$A$149,9,CALC!$C$57:$C$149,"<="&$A35)) -> 1,120 | K35: =IF(COUNTIFS(CALC!$A$57:$A$149,10,CALC!$C$57:$C$149,"<="&$A35)=0,"",CONSTANTS!$D$83+SUMIFS(CALC!$O$57:$O$149,CALC!$A$57:$A$149,10,CALC!$C$57:$C$149,"<="&$A35)+SUMIFS(CALC!$N$57:$N$149,CALC!$A$57:$A$149,10,CALC!$C$57:$C$149,"<="&$A35)) -> 1,579
A36: 4 | B36: =IF(COUNTIFS(CALC!$A$57:$A$149,1,CALC!$C$57:$C$149,"<="&$A36)=0,"",CONSTANTS!$D$74+SUMIFS(CALC!$O$57:$O$149,CALC!$A$57:$A$149,1,CALC!$C$57:$C$149,"<="&$A36)+SUMIFS(CALC!$N$57:$N$149,CALC!$A$57:$A$149,1,CALC!$C$57:$C$149,"<="&$A36)) -> 874 | C36: =IF(COUNTIFS(CALC!$A$57:$A$149,2,CALC!$C$57:$C$149,"<="&$A36)=0,"",CONSTANTS!$D$75+SUMIFS(CALC!$O$57:$O$149,CALC!$A$57:$A$149,2,CALC!$C$57:$C$149,"<="&$A36)+SUMIFS(CALC!$N$57:$N$149,CALC!$A$57:$A$149,2,CALC!$C$57:$C$149,"<="&$A36)) -> 854 | D36: =IF(COUNTIFS(CALC!$A$57:$A$149,3,CALC!$C$57:$C$149,"<="&$A36)=0,"",CONSTANTS!$D$76+SUMIFS(CALC!$O$57:$O$149,CALC!$A$57:$A$149,3,CALC!$C$57:$C$149,"<="&$A36)+SUMIFS(CALC!$N$57:$N$149,CALC!$A$57:$A$149,3,CALC!$C$57:$C$149,"<="&$A36)) -> 924 | E36: =IF(COUNTIFS(CALC!$A$57:$A$149,4,CALC!$C$57:$C$149,"<="&$A36)=0,"",CONSTANTS!$D$77+SUMIFS(CALC!$O$57:$O$149,CALC!$A$57:$A$149,4,CALC!$C$57:$C$149,"<="&$A36)+SUMIFS(CALC!$N$57:$N$149,CALC!$A$57:$A$149,4,CALC!$C$57:$C$149,"<="&$A36)) -> 996 | F36: =IF(COUNTIFS(CALC!$A$57:$A$149,5,CALC!$C$57:$C$149,"<="&$A36)=0,"",CONSTANTS!$D$78+SUMIFS(CALC!$O$57:$O$149,CALC!$A$57:$A$149,5,CALC!$C$57:$C$149,"<="&$A36)+SUMIFS(CALC!$N$57:$N$149,CALC!$A$57:$A$149,5,CALC!$C$57:$C$149,"<="&$A36)) -> 1,068 | G36: =IF(COUNTIFS(CALC!$A$57:$A$149,6,CALC!$C$57:$C$149,"<="&$A36)=0,"",CONSTANTS!$D$79+SUMIFS(CALC!$O$57:$O$149,CALC!$A$57:$A$149,6,CALC!$C$57:$C$149,"<="&$A36)+SUMIFS(CALC!$N$57:$N$149,CALC!$A$57:$A$149,6,CALC!$C$57:$C$149,"<="&$A36)) -> 1,214 | H36: =IF(COUNTIFS(CALC!$A$57:$A$149,7,CALC!$C$57:$C$149,"<="&$A36)=0,"",CONSTANTS!$D$80+SUMIFS(CALC!$O$57:$O$149,CALC!$A$57:$A$149,7,CALC!$C$57:$C$149,"<="&$A36)+SUMIFS(CALC!$N$57:$N$149,CALC!$A$57:$A$149,7,CALC!$C$57:$C$149,"<="&$A36)) -> 1,639 | I36: =IF(COUNTIFS(CALC!$A$57:$A$149,8,CALC!$C$57:$C$149,"<="&$A36)=0,"",CONSTANTS!$D$81+SUMIFS(CALC!$O$57:$O$149,CALC!$A$57:$A$149,8,CALC!$C$57:$C$149,"<="&$A36)+SUMIFS(CALC!$N$57:$N$149,CALC!$A$57:$A$149,8,CALC!$C$57:$C$149,"<="&$A36)) -> 1,394 | J36: =IF(COUNTIFS(CALC!$A$57:$A$149,9,CALC!$C$57:$C$149,"<="&$A36)=0,"",CONSTANTS!$D$82+SUMIFS(CALC!$O$57:$O$149,CALC!$A$57:$A$149,9,CALC!$C$57:$C$149,"<="&$A36)+SUMIFS(CALC!$N$57:$N$149,CALC!$A$57:$A$149,9,CALC!$C$57:$C$149,"<="&$A36)) -> 1,254 | K36: =IF(COUNTIFS(CALC!$A$57:$A$149,10,CALC!$C$57:$C$149,"<="&$A36)=0,"",CONSTANTS!$D$83+SUMIFS(CALC!$O$57:$O$149,CALC!$A$57:$A$149,10,CALC!$C$57:$C$149,"<="&$A36)+SUMIFS(CALC!$N$57:$N$149,CALC!$A$57:$A$149,10,CALC!$C$57:$C$149,"<="&$A36)) -> 1,953
A37: 5 | B37: =IF(COUNTIFS(CALC!$A$57:$A$149,1,CALC!$C$57:$C$149,"<="&$A37)=0,"",CONSTANTS!$D$74+SUMIFS(CALC!$O$57:$O$149,CALC!$A$57:$A$149,1,CALC!$C$57:$C$149,"<="&$A37)+SUMIFS(CALC!$N$57:$N$149,CALC!$A$57:$A$149,1,CALC!$C$57:$C$149,"<="&$A37)) -> 954 | C37: =IF(COUNTIFS(CALC!$A$57:$A$149,2,CALC!$C$57:$C$149,"<="&$A37)=0,"",CONSTANTS!$D$75+SUMIFS(CALC!$O$57:$O$149,CALC!$A$57:$A$149,2,CALC!$C$57:$C$149,"<="&$A37)+SUMIFS(CALC!$N$57:$N$149,CALC!$A$57:$A$149,2,CALC!$C$57:$C$149,"<="&$A37)) -> 1,074 | D37: =IF(COUNTIFS(CALC!$A$57:$A$149,3,CALC!$C$57:$C$149,"<="&$A37)=0,"",CONSTANTS!$D$76+SUMIFS(CALC!$O$57:$O$149,CALC!$A$57:$A$149,3,CALC!$C$57:$C$149,"<="&$A37)+SUMIFS(CALC!$N$57:$N$149,CALC!$A$57:$A$149,3,CALC!$C$57:$C$149,"<="&$A37)) -> 1,112 | E37: =IF(COUNTIFS(CALC!$A$57:$A$149,4,CALC!$C$57:$C$149,"<="&$A37)=0,"",CONSTANTS!$D$77+SUMIFS(CALC!$O$57:$O$149,CALC!$A$57:$A$149,4,CALC!$C$57:$C$149,"<="&$A37)+SUMIFS(CALC!$N$57:$N$149,CALC!$A$57:$A$149,4,CALC!$C$57:$C$149,"<="&$A37)) -> 1,208 | F37: =IF(COUNTIFS(CALC!$A$57:$A$149,5,CALC!$C$57:$C$149,"<="&$A37)=0,"",CONSTANTS!$D$78+SUMIFS(CALC!$O$57:$O$149,CALC!$A$57:$A$149,5,CALC!$C$57:$C$149,"<="&$A37)+SUMIFS(CALC!$N$57:$N$149,CALC!$A$57:$A$149,5,CALC!$C$57:$C$149,"<="&$A37)) -> 1,256 | G37: =IF(COUNTIFS(CALC!$A$57:$A$149,6,CALC!$C$57:$C$149,"<="&$A37)=0,"",CONSTANTS!$D$79+SUMIFS(CALC!$O$57:$O$149,CALC!$A$57:$A$149,6,CALC!$C$57:$C$149,"<="&$A37)+SUMIFS(CALC!$N$57:$N$149,CALC!$A$57:$A$149,6,CALC!$C$57:$C$149,"<="&$A37)) -> 1,402 | H37: =IF(COUNTIFS(CALC!$A$57:$A$149,7,CALC!$C$57:$C$149,"<="&$A37)=0,"",CONSTANTS!$D$80+SUMIFS(CALC!$O$57:$O$149,CALC!$A$57:$A$149,7,CALC!$C$57:$C$149,"<="&$A37)+SUMIFS(CALC!$N$57:$N$149,CALC!$A$57:$A$149,7,CALC!$C$57:$C$149,"<="&$A37)) -> 1,827 | I37: =IF(COUNTIFS(CALC!$A$57:$A$149,8,CALC!$C$57:$C$149,"<="&$A37)=0,"",CONSTANTS!$D$81+SUMIFS(CALC!$O$57:$O$149,CALC!$A$57:$A$149,8,CALC!$C$57:$C$149,"<="&$A37)+SUMIFS(CALC!$N$57:$N$149,CALC!$A$57:$A$149,8,CALC!$C$57:$C$149,"<="&$A37)) -> 1,764 | J37: =IF(COUNTIFS(CALC!$A$57:$A$149,9,CALC!$C$57:$C$149,"<="&$A37)=0,"",CONSTANTS!$D$82+SUMIFS(CALC!$O$57:$O$149,CALC!$A$57:$A$149,9,CALC!$C$57:$C$149,"<="&$A37)+SUMIFS(CALC!$N$57:$N$149,CALC!$A$57:$A$149,9,CALC!$C$57:$C$149,"<="&$A37)) -> 1,490 | K37: =IF(COUNTIFS(CALC!$A$57:$A$149,10,CALC!$C$57:$C$149,"<="&$A37)=0,"",CONSTANTS!$D$83+SUMIFS(CALC!$O$57:$O$149,CALC!$A$57:$A$149,10,CALC!$C$57:$C$149,"<="&$A37)+SUMIFS(CALC!$N$57:$N$149,CALC!$A$57:$A$149,10,CALC!$C$57:$C$149,"<="&$A37)) -> 2,273
A38: 6 | B38: =IF(COUNTIFS(CALC!$A$57:$A$149,1,CALC!$C$57:$C$149,"<="&$A38)=0,"",CONSTANTS!$D$74+SUMIFS(CALC!$O$57:$O$149,CALC!$A$57:$A$149,1,CALC!$C$57:$C$149,"<="&$A38)+SUMIFS(CALC!$N$57:$N$149,CALC!$A$57:$A$149,1,CALC!$C$57:$C$149,"<="&$A38)) -> 1,160 | C38: =IF(COUNTIFS(CALC!$A$57:$A$149,2,CALC!$C$57:$C$149,"<="&$A38)=0,"",CONSTANTS!$D$75+SUMIFS(CALC!$O$57:$O$149,CALC!$A$57:$A$149,2,CALC!$C$57:$C$149,"<="&$A38)+SUMIFS(CALC!$N$57:$N$149,CALC!$A$57:$A$149,2,CALC!$C$57:$C$149,"<="&$A38)) -> 1,208 | D38: =IF(COUNTIFS(CALC!$A$57:$A$149,3,CALC!$C$57:$C$149,"<="&$A38)=0,"",CONSTANTS!$D$76+SUMIFS(CALC!$O$57:$O$149,CALC!$A$57:$A$149,3,CALC!$C$57:$C$149,"<="&$A38)+SUMIFS(CALC!$N$57:$N$149,CALC!$A$57:$A$149,3,CALC!$C$57:$C$149,"<="&$A38)) -> 1,202 | E38: =IF(COUNTIFS(CALC!$A$57:$A$149,4,CALC!$C$57:$C$149,"<="&$A38)=0,"",CONSTANTS!$D$77+SUMIFS(CALC!$O$57:$O$149,CALC!$A$57:$A$149,4,CALC!$C$57:$C$149,"<="&$A38)+SUMIFS(CALC!$N$57:$N$149,CALC!$A$57:$A$149,4,CALC!$C$57:$C$149,"<="&$A38)) -> 1,350 | F38: =IF(COUNTIFS(CALC!$A$57:$A$149,5,CALC!$C$57:$C$149,"<="&$A38)=0,"",CONSTANTS!$D$78+SUMIFS(CALC!$O$57:$O$149,CALC!$A$57:$A$149,5,CALC!$C$57:$C$149,"<="&$A38)+SUMIFS(CALC!$N$57:$N$149,CALC!$A$57:$A$149,5,CALC!$C$57:$C$149,"<="&$A38)) -> 1,498 | G38: =IF(COUNTIFS(CALC!$A$57:$A$149,6,CALC!$C$57:$C$149,"<="&$A38)=0,"",CONSTANTS!$D$79+SUMIFS(CALC!$O$57:$O$149,CALC!$A$57:$A$149,6,CALC!$C$57:$C$149,"<="&$A38)+SUMIFS(CALC!$N$57:$N$149,CALC!$A$57:$A$149,6,CALC!$C$57:$C$149,"<="&$A38)) -> 1,586 | H38: =IF(COUNTIFS(CALC!$A$57:$A$149,7,CALC!$C$57:$C$149,"<="&$A38)=0,"",CONSTANTS!$D$80+SUMIFS(CALC!$O$57:$O$149,CALC!$A$57:$A$149,7,CALC!$C$57:$C$149,"<="&$A38)+SUMIFS(CALC!$N$57:$N$149,CALC!$A$57:$A$149,7,CALC!$C$57:$C$149,"<="&$A38)) -> 1,987 | I38: =IF(COUNTIFS(CALC!$A$57:$A$149,8,CALC!$C$57:$C$149,"<="&$A38)=0,"",CONSTANTS!$D$81+SUMIFS(CALC!$O$57:$O$149,CALC!$A$57:$A$149,8,CALC!$C$57:$C$149,"<="&$A38)+SUMIFS(CALC!$N$57:$N$149,CALC!$A$57:$A$149,8,CALC!$C$57:$C$149,"<="&$A38)) -> 1,974 | J38: =IF(COUNTIFS(CALC!$A$57:$A$149,9,CALC!$C$57:$C$149,"<="&$A38)=0,"",CONSTANTS!$D$82+SUMIFS(CALC!$O$57:$O$149,CALC!$A$57:$A$149,9,CALC!$C$57:$C$149,"<="&$A38)+SUMIFS(CALC!$N$57:$N$149,CALC!$A$57:$A$149,9,CALC!$C$57:$C$149,"<="&$A38)) -> 2,134 | K38: =IF(COUNTIFS(CALC!$A$57:$A$149,10,CALC!$C$57:$C$149,"<="&$A38)=0,"",CONSTANTS!$D$83+SUMIFS(CALC!$O$57:$O$149,CALC!$A$57:$A$149,10,CALC!$C$57:$C$149,"<="&$A38)+SUMIFS(CALC!$N$57:$N$149,CALC!$A$57:$A$149,10,CALC!$C$57:$C$149,"<="&$A38)) -> 2,633
A39: 7 | B39: =IF(COUNTIFS(CALC!$A$57:$A$149,1,CALC!$C$57:$C$149,"<="&$A39)=0,"",CONSTANTS!$D$74+SUMIFS(CALC!$O$57:$O$149,CALC!$A$57:$A$149,1,CALC!$C$57:$C$149,"<="&$A39)+SUMIFS(CALC!$N$57:$N$149,CALC!$A$57:$A$149,1,CALC!$C$57:$C$149,"<="&$A39)) -> 1,497 | C39: =IF(COUNTIFS(CALC!$A$57:$A$149,2,CALC!$C$57:$C$149,"<="&$A39)=0,"",CONSTANTS!$D$75+SUMIFS(CALC!$O$57:$O$149,CALC!$A$57:$A$149,2,CALC!$C$57:$C$149,"<="&$A39)+SUMIFS(CALC!$N$57:$N$149,CALC!$A$57:$A$149,2,CALC!$C$57:$C$149,"<="&$A39)) -> 1,542 | D39: =IF(COUNTIFS(CALC!$A$57:$A$149,3,CALC!$C$57:$C$149,"<="&$A39)=0,"",CONSTANTS!$D$76+SUMIFS(CALC!$O$57:$O$149,CALC!$A$57:$A$149,3,CALC!$C$57:$C$149,"<="&$A39)+SUMIFS(CALC!$N$57:$N$149,CALC!$A$57:$A$149,3,CALC!$C$57:$C$149,"<="&$A39)) -> 1,466 | E39: =IF(COUNTIFS(CALC!$A$57:$A$149,4,CALC!$C$57:$C$149,"<="&$A39)=0,"",CONSTANTS!$D$77+SUMIFS(CALC!$O$57:$O$149,CALC!$A$57:$A$149,4,CALC!$C$57:$C$149,"<="&$A39)+SUMIFS(CALC!$N$57:$N$149,CALC!$A$57:$A$149,4,CALC!$C$57:$C$149,"<="&$A39)) -> 1,538 | F39: =IF(COUNTIFS(CALC!$A$57:$A$149,5,CALC!$C$57:$C$149,"<="&$A39)=0,"",CONSTANTS!$D$78+SUMIFS(CALC!$O$57:$O$149,CALC!$A$57:$A$149,5,CALC!$C$57:$C$149,"<="&$A39)+SUMIFS(CALC!$N$57:$N$149,CALC!$A$57:$A$149,5,CALC!$C$57:$C$149,"<="&$A39)) -> 1,798 | G39: =IF(COUNTIFS(CALC!$A$57:$A$149,6,CALC!$C$57:$C$149,"<="&$A39)=0,"",CONSTANTS!$D$79+SUMIFS(CALC!$O$57:$O$149,CALC!$A$57:$A$149,6,CALC!$C$57:$C$149,"<="&$A39)+SUMIFS(CALC!$N$57:$N$149,CALC!$A$57:$A$149,6,CALC!$C$57:$C$149,"<="&$A39)) -> 1,846 | H39: =IF(COUNTIFS(CALC!$A$57:$A$149,7,CALC!$C$57:$C$149,"<="&$A39)=0,"",CONSTANTS!$D$80+SUMIFS(CALC!$O$57:$O$149,CALC!$A$57:$A$149,7,CALC!$C$57:$C$149,"<="&$A39)+SUMIFS(CALC!$N$57:$N$149,CALC!$A$57:$A$149,7,CALC!$C$57:$C$149,"<="&$A39)) -> 2,261 | I39: =IF(COUNTIFS(CALC!$A$57:$A$149,8,CALC!$C$57:$C$149,"<="&$A39)=0,"",CONSTANTS!$D$81+SUMIFS(CALC!$O$57:$O$149,CALC!$A$57:$A$149,8,CALC!$C$57:$C$149,"<="&$A39)+SUMIFS(CALC!$N$57:$N$149,CALC!$A$57:$A$149,8,CALC!$C$57:$C$149,"<="&$A39)) -> 2,299 | J39: =IF(COUNTIFS(CALC!$A$57:$A$149,9,CALC!$C$57:$C$149,"<="&$A39)=0,"",CONSTANTS!$D$82+SUMIFS(CALC!$O$57:$O$149,CALC!$A$57:$A$149,9,CALC!$C$57:$C$149,"<="&$A39)+SUMIFS(CALC!$N$57:$N$149,CALC!$A$57:$A$149,9,CALC!$C$57:$C$149,"<="&$A39)) -> 2,384 | K39: =IF(COUNTIFS(CALC!$A$57:$A$149,10,CALC!$C$57:$C$149,"<="&$A39)=0,"",CONSTANTS!$D$83+SUMIFS(CALC!$O$57:$O$149,CALC!$A$57:$A$149,10,CALC!$C$57:$C$149,"<="&$A39)+SUMIFS(CALC!$N$57:$N$149,CALC!$A$57:$A$149,10,CALC!$C$57:$C$149,"<="&$A39)) -> 2,967
A40: 8 | B40: =IF(COUNTIFS(CALC!$A$57:$A$149,1,CALC!$C$57:$C$149,"<="&$A40)=0,"",CONSTANTS!$D$74+SUMIFS(CALC!$O$57:$O$149,CALC!$A$57:$A$149,1,CALC!$C$57:$C$149,"<="&$A40)+SUMIFS(CALC!$N$57:$N$149,CALC!$A$57:$A$149,1,CALC!$C$57:$C$149,"<="&$A40)) -> 1,641 | C40: =IF(COUNTIFS(CALC!$A$57:$A$149,2,CALC!$C$57:$C$149,"<="&$A40)=0,"",CONSTANTS!$D$75+SUMIFS(CALC!$O$57:$O$149,CALC!$A$57:$A$149,2,CALC!$C$57:$C$149,"<="&$A40)+SUMIFS(CALC!$N$57:$N$149,CALC!$A$57:$A$149,2,CALC!$C$57:$C$149,"<="&$A40)) -> 1,686 | D40: =IF(COUNTIFS(CALC!$A$57:$A$149,3,CALC!$C$57:$C$149,"<="&$A40)=0,"",CONSTANTS!$D$76+SUMIFS(CALC!$O$57:$O$149,CALC!$A$57:$A$149,3,CALC!$C$57:$C$149,"<="&$A40)+SUMIFS(CALC!$N$57:$N$149,CALC!$A$57:$A$149,3,CALC!$C$57:$C$149,"<="&$A40)) -> 1,718 | E40: =IF(COUNTIFS(CALC!$A$57:$A$149,4,CALC!$C$57:$C$149,"<="&$A40)=0,"",CONSTANTS!$D$77+SUMIFS(CALC!$O$57:$O$149,CALC!$A$57:$A$149,4,CALC!$C$57:$C$149,"<="&$A40)+SUMIFS(CALC!$N$57:$N$149,CALC!$A$57:$A$149,4,CALC!$C$57:$C$149,"<="&$A40)) -> 1,790 | F40: =IF(COUNTIFS(CALC!$A$57:$A$149,5,CALC!$C$57:$C$149,"<="&$A40)=0,"",CONSTANTS!$D$78+SUMIFS(CALC!$O$57:$O$149,CALC!$A$57:$A$149,5,CALC!$C$57:$C$149,"<="&$A40)+SUMIFS(CALC!$N$57:$N$149,CALC!$A$57:$A$149,5,CALC!$C$57:$C$149,"<="&$A40)) -> 2,050 | G40: =IF(COUNTIFS(CALC!$A$57:$A$149,6,CALC!$C$57:$C$149,"<="&$A40)=0,"",CONSTANTS!$D$79+SUMIFS(CALC!$O$57:$O$149,CALC!$A$57:$A$149,6,CALC!$C$57:$C$149,"<="&$A40)+SUMIFS(CALC!$N$57:$N$149,CALC!$A$57:$A$149,6,CALC!$C$57:$C$149,"<="&$A40)) -> 2,060 | H40: =IF(COUNTIFS(CALC!$A$57:$A$149,7,CALC!$C$57:$C$149,"<="&$A40)=0,"",CONSTANTS!$D$80+SUMIFS(CALC!$O$57:$O$149,CALC!$A$57:$A$149,7,CALC!$C$57:$C$149,"<="&$A40)+SUMIFS(CALC!$N$57:$N$149,CALC!$A$57:$A$149,7,CALC!$C$57:$C$149,"<="&$A40)) -> 2,523 | I40: =IF(COUNTIFS(CALC!$A$57:$A$149,8,CALC!$C$57:$C$149,"<="&$A40)=0,"",CONSTANTS!$D$81+SUMIFS(CALC!$O$57:$O$149,CALC!$A$57:$A$149,8,CALC!$C$57:$C$149,"<="&$A40)+SUMIFS(CALC!$N$57:$N$149,CALC!$A$57:$A$149,8,CALC!$C$57:$C$149,"<="&$A40)) -> 2,539 | J40: =IF(COUNTIFS(CALC!$A$57:$A$149,9,CALC!$C$57:$C$149,"<="&$A40)=0,"",CONSTANTS!$D$82+SUMIFS(CALC!$O$57:$O$149,CALC!$A$57:$A$149,9,CALC!$C$57:$C$149,"<="&$A40)+SUMIFS(CALC!$N$57:$N$149,CALC!$A$57:$A$149,9,CALC!$C$57:$C$149,"<="&$A40)) -> 2,384 | K40: =IF(COUNTIFS(CALC!$A$57:$A$149,10,CALC!$C$57:$C$149,"<="&$A40)=0,"",CONSTANTS!$D$83+SUMIFS(CALC!$O$57:$O$149,CALC!$A$57:$A$149,10,CALC!$C$57:$C$149,"<="&$A40)+SUMIFS(CALC!$N$57:$N$149,CALC!$A$57:$A$149,10,CALC!$C$57:$C$149,"<="&$A40)) -> 3,193
A41: 9 | B41: =IF(COUNTIFS(CALC!$A$57:$A$149,1,CALC!$C$57:$C$149,"<="&$A41)=0,"",CONSTANTS!$D$74+SUMIFS(CALC!$O$57:$O$149,CALC!$A$57:$A$149,1,CALC!$C$57:$C$149,"<="&$A41)+SUMIFS(CALC!$N$57:$N$149,CALC!$A$57:$A$149,1,CALC!$C$57:$C$149,"<="&$A41)) -> 1,641 | C41: =IF(COUNTIFS(CALC!$A$57:$A$149,2,CALC!$C$57:$C$149,"<="&$A41)=0,"",CONSTANTS!$D$75+SUMIFS(CALC!$O$57:$O$149,CALC!$A$57:$A$149,2,CALC!$C$57:$C$149,"<="&$A41)+SUMIFS(CALC!$N$57:$N$149,CALC!$A$57:$A$149,2,CALC!$C$57:$C$149,"<="&$A41)) -> 1,686 | D41: =IF(COUNTIFS(CALC!$A$57:$A$149,3,CALC!$C$57:$C$149,"<="&$A41)=0,"",CONSTANTS!$D$76+SUMIFS(CALC!$O$57:$O$149,CALC!$A$57:$A$149,3,CALC!$C$57:$C$149,"<="&$A41)+SUMIFS(CALC!$N$57:$N$149,CALC!$A$57:$A$149,3,CALC!$C$57:$C$149,"<="&$A41)) -> 2,046 | E41: =IF(COUNTIFS(CALC!$A$57:$A$149,4,CALC!$C$57:$C$149,"<="&$A41)=0,"",CONSTANTS!$D$77+SUMIFS(CALC!$O$57:$O$149,CALC!$A$57:$A$149,4,CALC!$C$57:$C$149,"<="&$A41)+SUMIFS(CALC!$N$57:$N$149,CALC!$A$57:$A$149,4,CALC!$C$57:$C$149,"<="&$A41)) -> 2,126 | F41: =IF(COUNTIFS(CALC!$A$57:$A$149,5,CALC!$C$57:$C$149,"<="&$A41)=0,"",CONSTANTS!$D$78+SUMIFS(CALC!$O$57:$O$149,CALC!$A$57:$A$149,5,CALC!$C$57:$C$149,"<="&$A41)+SUMIFS(CALC!$N$57:$N$149,CALC!$A$57:$A$149,5,CALC!$C$57:$C$149,"<="&$A41)) -> 2,262 | G41: =IF(COUNTIFS(CALC!$A$57:$A$149,6,CALC!$C$57:$C$149,"<="&$A41)=0,"",CONSTANTS!$D$79+SUMIFS(CALC!$O$57:$O$149,CALC!$A$57:$A$149,6,CALC!$C$57:$C$149,"<="&$A41)+SUMIFS(CALC!$N$57:$N$149,CALC!$A$57:$A$149,6,CALC!$C$57:$C$149,"<="&$A41)) -> 2,426 | H41: =IF(COUNTIFS(CALC!$A$57:$A$149,7,CALC!$C$57:$C$149,"<="&$A41)=0,"",CONSTANTS!$D$80+SUMIFS(CALC!$O$57:$O$149,CALC!$A$57:$A$149,7,CALC!$C$57:$C$149,"<="&$A41)+SUMIFS(CALC!$N$57:$N$149,CALC!$A$57:$A$149,7,CALC!$C$57:$C$149,"<="&$A41)) -> 2,845 | I41: =IF(COUNTIFS(CALC!$A$57:$A$149,8,CALC!$C$57:$C$149,"<="&$A41)=0,"",CONSTANTS!$D$81+SUMIFS(CALC!$O$57:$O$149,CALC!$A$57:$A$149,8,CALC!$C$57:$C$149,"<="&$A41)+SUMIFS(CALC!$N$57:$N$149,CALC!$A$57:$A$149,8,CALC!$C$57:$C$149,"<="&$A41)) -> 2,939 | J41: =IF(COUNTIFS(CALC!$A$57:$A$149,9,CALC!$C$57:$C$149,"<="&$A41)=0,"",CONSTANTS!$D$82+SUMIFS(CALC!$O$57:$O$149,CALC!$A$57:$A$149,9,CALC!$C$57:$C$149,"<="&$A41)+SUMIFS(CALC!$N$57:$N$149,CALC!$A$57:$A$149,9,CALC!$C$57:$C$149,"<="&$A41)) -> 2,384 | K41: =IF(COUNTIFS(CALC!$A$57:$A$149,10,CALC!$C$57:$C$149,"<="&$A41)=0,"",CONSTANTS!$D$83+SUMIFS(CALC!$O$57:$O$149,CALC!$A$57:$A$149,10,CALC!$C$57:$C$149,"<="&$A41)+SUMIFS(CALC!$N$57:$N$149,CALC!$A$57:$A$149,10,CALC!$C$57:$C$149,"<="&$A41)) -> 3,554
A42: 10 | B42: =IF(COUNTIFS(CALC!$A$57:$A$149,1,CALC!$C$57:$C$149,"<="&$A42)=0,"",CONSTANTS!$D$74+SUMIFS(CALC!$O$57:$O$149,CALC!$A$57:$A$149,1,CALC!$C$57:$C$149,"<="&$A42)+SUMIFS(CALC!$N$57:$N$149,CALC!$A$57:$A$149,1,CALC!$C$57:$C$149,"<="&$A42)) -> 1,641 | C42: =IF(COUNTIFS(CALC!$A$57:$A$149,2,CALC!$C$57:$C$149,"<="&$A42)=0,"",CONSTANTS!$D$75+SUMIFS(CALC!$O$57:$O$149,CALC!$A$57:$A$149,2,CALC!$C$57:$C$149,"<="&$A42)+SUMIFS(CALC!$N$57:$N$149,CALC!$A$57:$A$149,2,CALC!$C$57:$C$149,"<="&$A42)) -> 1,686 | D42: =IF(COUNTIFS(CALC!$A$57:$A$149,3,CALC!$C$57:$C$149,"<="&$A42)=0,"",CONSTANTS!$D$76+SUMIFS(CALC!$O$57:$O$149,CALC!$A$57:$A$149,3,CALC!$C$57:$C$149,"<="&$A42)+SUMIFS(CALC!$N$57:$N$149,CALC!$A$57:$A$149,3,CALC!$C$57:$C$149,"<="&$A42)) -> 2,288 | E42: =IF(COUNTIFS(CALC!$A$57:$A$149,4,CALC!$C$57:$C$149,"<="&$A42)=0,"",CONSTANTS!$D$77+SUMIFS(CALC!$O$57:$O$149,CALC!$A$57:$A$149,4,CALC!$C$57:$C$149,"<="&$A42)+SUMIFS(CALC!$N$57:$N$149,CALC!$A$57:$A$149,4,CALC!$C$57:$C$149,"<="&$A42)) -> 2,459 | F42: =IF(COUNTIFS(CALC!$A$57:$A$149,5,CALC!$C$57:$C$149,"<="&$A42)=0,"",CONSTANTS!$D$78+SUMIFS(CALC!$O$57:$O$149,CALC!$A$57:$A$149,5,CALC!$C$57:$C$149,"<="&$A42)+SUMIFS(CALC!$N$57:$N$149,CALC!$A$57:$A$149,5,CALC!$C$57:$C$149,"<="&$A42)) -> 2,669 | G42: =IF(COUNTIFS(CALC!$A$57:$A$149,6,CALC!$C$57:$C$149,"<="&$A42)=0,"",CONSTANTS!$D$79+SUMIFS(CALC!$O$57:$O$149,CALC!$A$57:$A$149,6,CALC!$C$57:$C$149,"<="&$A42)+SUMIFS(CALC!$N$57:$N$149,CALC!$A$57:$A$149,6,CALC!$C$57:$C$149,"<="&$A42)) -> 2,618 | H42: =IF(COUNTIFS(CALC!$A$57:$A$149,7,CALC!$C$57:$C$149,"<="&$A42)=0,"",CONSTANTS!$D$80+SUMIFS(CALC!$O$57:$O$149,CALC!$A$57:$A$149,7,CALC!$C$57:$C$149,"<="&$A42)+SUMIFS(CALC!$N$57:$N$149,CALC!$A$57:$A$149,7,CALC!$C$57:$C$149,"<="&$A42)) -> 3,129 | I42: =IF(COUNTIFS(CALC!$A$57:$A$149,8,CALC!$C$57:$C$149,"<="&$A42)=0,"",CONSTANTS!$D$81+SUMIFS(CALC!$O$57:$O$149,CALC!$A$57:$A$149,8,CALC!$C$57:$C$149,"<="&$A42)+SUMIFS(CALC!$N$57:$N$149,CALC!$A$57:$A$149,8,CALC!$C$57:$C$149,"<="&$A42)) -> 3,354 | J42: =IF(COUNTIFS(CALC!$A$57:$A$149,9,CALC!$C$57:$C$149,"<="&$A42)=0,"",CONSTANTS!$D$82+SUMIFS(CALC!$O$57:$O$149,CALC!$A$57:$A$149,9,CALC!$C$57:$C$149,"<="&$A42)+SUMIFS(CALC!$N$57:$N$149,CALC!$A$57:$A$149,9,CALC!$C$57:$C$149,"<="&$A42)) -> 2,384 | K42: =IF(COUNTIFS(CALC!$A$57:$A$149,10,CALC!$C$57:$C$149,"<="&$A42)=0,"",CONSTANTS!$D$83+SUMIFS(CALC!$O$57:$O$149,CALC!$A$57:$A$149,10,CALC!$C$57:$C$149,"<="&$A42)+SUMIFS(CALC!$N$57:$N$149,CALC!$A$57:$A$149,10,CALC!$C$57:$C$149,"<="&$A42)) -> 3,564
A44: 4 · MỐC CHẠM ĐƯỢC Ở WAVE NÀO
...
